Workbook
Name holidays: OFFSET(#REF!,1,0,COUNTA(#REF!),1)
Name valuevx: 42.314159

Sheet EV
A1: Earned Value Worksheet
A3: This worksheet is used to help calculate the Earned Value (EV) or Budgeted Cost of Work Performed (BCWP).
A4: Make sure that the WBS, Task Name, and TBC are identical to the table in the Report worksheet.
A5: Enter the % Complete for each task to calculate the cumulative earned value.
A7: Cumulative Earned Value (EV)
A8: WBS | B8: Task Name | C8: TBC | D8: Wk 1 | E8: Wk 2 | F8: Wk 3 | G8: Wk 4 | H8: Wk 5 | I8: Wk 6 | J8: Wk 7 | K8: Wk 8 | L8: Wk 9 | M8: Wk 10 | N8: Wk 11 | O8: Wk 12 | P8: Wk 13 | Q8: Wk 14
A9: =IF(ISBLANK(Report!A22)," - ",Report!A22) -> 1.1 | B9: =IF(ISBLANK(Report!B22)," - ",Report!B22) -> Arm prototyping & printing | C9: =Report!C22 -> 10 | E9: 0.15 | F9: 0.5 | G9: 1 | H9: 1 | I9: 1 | J9: 1 | K9: 1 | L9: 1 | M9: 1 | N9: 1 | O9: 1 | P9: 1 | Q9: 1
A10: =IF(ISBLANK(Report!A23)," - ",Report!A23) -> 1.2 | B10: =IF(ISBLANK(Report!B23)," - ",Report!B23) -> Assembling model | C10: =Report!C23 -> 4 | H10: 1 | I10: 1 | J10: 1 | K10: 1 | L10: 1 | M10: 1 | N10: 1 | O10: 1 | P10: 1 | Q10: 1
A11: =IF(ISBLANK(Report!A24)," - ",Report!A24) -> 2.1 | B11: =IF(ISBLANK(Report!B24)," - ",Report!B24) -> Sorter prototyping & wood cutting | C11: =Report!C24 -> 30 | M11: 1 | N11: 1 | O11: 1 | P11: 1 | Q11: 1
A12: =IF(ISBLANK(Report!A25)," - ",Report!A25) -> 2.2 | B12: =IF(ISBLANK(Report!B25)," - ",Report!B25) -> Change motor (hard+soft) | C12: =Report!C25 -> 10 | N12: 1 | O12: 1 | P12: 1 | Q12: 1
A13: =IF(ISBLANK(Report!A26)," - ",Report!A26) -> 2.3 | B13: =IF(ISBLANK(Report!B26)," - ",Report!B26) -> Assembling model | C13: =Report!C26 -> 4 | O13: 1 | P13: 1 | Q13: 1
A14: =IF(ISBLANK(Report!A27)," - ",Report!A27) -> 2.4 | B14: =IF(ISBLANK(Report!B27)," - ",Report!B27) -> Update code | C14: =Report!C27 -> 8 | O14: 1 | P14: 1 | Q14: 1
A15: =IF(ISBLANK(Report!A28)," - ",Report!A28) -> 3.1 | B15: =IF(ISBLANK(Report!B28)," - ",Report!B28) -> Code the Thrower | C15: =Report!C28 -> 20 | E15: 1 | F15: 1 | G15: 1 | H15: 1 | I15: 1 | J15: 1 | K15: 1 | L15: 1 | M15: 1 | N15: 1 | O15: 1 | P15: 1 | Q15: 1
A16: =IF(ISBLANK(Report!A29)," - ",Report!A29) -> 3.2 | B16: =IF(ISBLANK(Report!B29)," - ",Report!B29) -> Electrical mounting | C16: =Report!C29 -> 20 | E16: 1 | F16: 1 | G16: 1 | H16: 1 | I16: 1 | J16: 1 | K16: 1 | L16: 1 | M16: 1 | N16: 1 | O16: 1 | P16: 1 | Q16: 1
A17: =IF(ISBLANK(Report!A30)," - ",Report!A30) -> 3.3 | B17: =IF(ISBLANK(Report!B30)," - ",Report!B30) -> Datasheet on PWM | C17: =Report!C30 -> 8 | F17: 1 | G17: 1 | H17: 1 | I17: 1 | J17: 1 | K17: 1 | L17: 1 | M17: 1 | N17: 1 | O17: 1 | P17: 1 | Q17: 1
A18: =IF(ISBLANK(Report!A31)," - ",Report!A31) -> 4.1 | B18: =IF(ISBLANK(Report!B31)," - ",Report!B31) -> Executable & Initialisation fn | C18: =Report!C31 -> 20 | G18: 0.4 | H18: 0.6 | I18: 1 | J18: 1 | K18: 1 | L18: 1 | M18: 1 | N18: 1 | O18: 1 | P18: 1 | Q18: 1
A19: =IF(ISBLANK(Report!A32)," - ",Report!A32) -> 4.2 | B19: =IF(ISBLANK(Report!B32)," - ",Report!B32) -> Cleaning code, error cabling ... | C19: =Report!C32 -> 32 | H19: 0.5 | I19: 1 | J19: 1 | K19: 1 | L19: 1 | M19: 1 | N19: 1 | O19: 1 | P19: 1 | Q19: 1
A20: =IF(ISBLANK(Report!A33)," - ",Report!A33) -> 4.3 | B20: =IF(ISBLANK(Report!B33)," - ",Report!B33) -> Update all RIO cards | C20: =Report!C33 -> 4 | I20: 1 | J20: 1 | K20: 1 | L20: 1 | M20: 1 | N20: 1 | O20: 1 | P20: 1 | Q20: 1
A21: =IF(ISBLANK(Report!A34)," - ",Report!A34) -> 4.4 | B21: =IF(ISBLANK(Report!B34)," - ",Report!B34) -> Real Time | C21: =Report!C34 -> 56
A22: =IF(ISBLANK(Report!A35)," - ",Report!A35) -> 5.1 | B22: =IF(ISBLANK(Report!B35)," - ",Report!B35) -> Supply PCB prototyping | C22: =Report!C35 -> 28 | E22: 0.15 | F22: 0.3 | G22: 0.45 | H22: 0.6 | I22: 0.8 | J22: 0.8 | K22: 0.8 | L22: 0.8 | M22: 0.8 | N22: 0.8 | O22: 0.8 | P22: 1 | Q22: 1
A23: =IF(ISBLANK(Report!A36)," - ",Report!A36) -> 5.2 | B23: =IF(ISBLANK(Report!B36)," - ",Report!B36) -> Data PCB Prototyping | C23: =Report!C36 -> 80 | J23: 0.3 | K23: 0.5 | L23: 0.8 | M23: 1 | N23: 1 | O23: 1 | P23: 1 | Q23: 1
A24: =IF(ISBLANK(Report!A37)," - ",Report!A37) -> 5.3 | B24: =IF(ISBLANK(Report!B37)," - ",Report!B37) -> PCB Deployment & integration | C24: =Report!C37 -> 32 | M24: 0.15 | N24: 0.5 | O24: 0.6 | P24: 0.8 | Q24: 1
A25: =IF(ISBLANK(Report!A38)," - ",Report!A38) -> 6.1 | B25: =IF(ISBLANK(Report!B38)," - ",Report!B38) -> Lidar - Research & command | C25: =Report!C38 -> 8 | K25: 1 | L25: 1 | M25: 1 | N25: 1 | O25: 1 | P25: 1 | Q25: 1
A26: =IF(ISBLANK(Report!A39)," - ",Report!A39) -> 6.2 | B26: =IF(ISBLANK(Report!B39)," - ",Report!B39) -> Lidar - Cabling & Data sending | C26: =Report!C39 -> 80 | M26: 0.5 | N26: 1 | O26: 1 | P26: 1 | Q26: 1
A27: =IF(ISBLANK(Report!A40)," - ",Report!A40) -> 6.3 | B27: =IF(ISBLANK(Report!B40)," - ",Report!B40) -> Lidar - Data treatment | C27: =Report!C40 -> 120 | N27: 0.33 | O27: 0.66 | P27: 0.8 | Q27: 1
A28: =IF(ISBLANK(Report!A41)," - ",Report!A41) -> 6.4 | B28: =IF(ISBLANK(Report!B41)," - ",Report!B41) -> Lidar - Integration on robot | C28: =Report!C41 -> 4 | P28: 1 | Q28: 1
A29: =IF(ISBLANK(Report!A42)," - ",Report!A42) -> 7.1 | B29: =IF(ISBLANK(Report!B42)," - ",Report!B42) -> Brainstorming Scenarii & details | C29: =Report!C42 -> 8 | E29: 0.2 | F29: 1 | G29: 1 | H29: 1 | I29: 1 | J29: 1 | K29: 1 | L29: 1 | M29: 1 | N29: 1 | O29: 1 | P29: 1 | Q29: 1
A30: =IF(ISBLANK(Report!A43)," - ",Report!A43) -> 7.2 | B30: =IF(ISBLANK(Report!B43)," - ",Report!B43) -> Scenario 1 | C30: =Report!C43 -> 16 | F30: 0.4 | G30: 1 | H30: 1 | I30: 1 | J30: 1 | K30: 1 | L30: 1 | M30: 1 | N30: 1 | O30: 1 | P30: 1 | Q30: 1
A31: =IF(ISBLANK(Report!A44)," - ",Report!A44) -> 7.3 | B31: =IF(ISBLANK(Report!B44)," - ",Report!B44) -> Scenario 2 | C31: =Report!C44 -> 100 | G31: 0.33 | H31: 0.33 | I31: 0.66 | J31: 1 | K31: 1 | L31: 1 | M31: 1 | N31: 1 | O31: 1 | P31: 1 | Q31: 1
A32: =IF(ISBLANK(Report!A45)," - ",Report!A45) -> 7.4 | B32: =IF(ISBLANK(Report!B45)," - ",Report!B45) -> Scenario 3 | C32: =Report!C45 -> 18 | P32: 0.8 | Q32: 0.9
A33: =IF(ISBLANK(Report!A46)," - ",Report!A46) -> 7.5 | B33: =IF(ISBLANK(Report!B46)," - ",Report!B46) -> Scenario 4 | C33: =Report!C46 -> 58
A34: =IF(ISBLANK(Report!A47)," - ",Report!A47) -> 8.1 | B34: =IF(ISBLANK(Report!B47)," - ",Report!B47) -> Preparation & Participation NI | C34: =Report!C47 -> 40 | D34: 1 | E34: 1 | F34: 1 | G34: 1 | H34: 1 | I34: 1 | J34: 1 | K34: 1 | L34: 1 | M34: 1 | N34: 1 | O34: 1 | P34: 1 | Q34: 1
A35: =IF(ISBLANK(Report!A48)," - ",Report!A48) -> 9.1 | B35: =IF(ISBLANK(Report!B48)," - ",Report!B48) -> Weekly & project management | C35: =Report!C48 -> 212 | D35: 0.06 | E35: 0.12 | F35: 0.18 | G35: 0.24 | H35: 0.3 | I35: 0.36 | J35: 0.42 | K35: 0.48 | L35: 0.54 | M35: 0.6 | N35: 0.66 | O35: 0.72 | P35: 0.75 | Q35: 1
A36: =IF(ISBLANK(Report!A49)," - ",Report!A49) -> 10.1 | B36: =IF(ISBLANK(Report!B49)," - ",Report!B49) -> Handover | C36: =Report!C49 -> 8 | Q36: 1
A37: =IF(ISBLANK(Report!A50)," - ",Report!A50) -> 11.1 | B37: =IF(ISBLANK(Report!B50)," - ",Report!B50) -> JPO presentation | C37: =Report!C50 -> 32 | J37: 0.5 | K37: 0.5 | L37: 0.5 | M37: 0.5 | N37: 0.5 | O37: 0.5 | P37: 1 | Q37: 1
A38: Insert new rows above this one
C39: Cumulative EV | D39: =SUMPRODUCT(D9:D38,$C$9:$C$38) -> 52.72 | E39: =SUMPRODUCT(E9:E38,$C$9:$C$38) -> 112.74 | F39: =SUMPRODUCT(F9:F38,$C$9:$C$38) -> 153.96 | G39: =SUMPRODUCT(G9:G38,$C$9:$C$38) -> 226.48 | H39: =SUMPRODUCT(H9:H38,$C$9:$C$38) -> 267.4 | I39: =SUMPRODUCT(I9:I38,$C$9:$C$38) -> 346.72 | J39: =SUMPRODUCT(J9:J38,$C$9:$C$38) -> 433.44 | K39: =SUMPRODUCT(K9:K38,$C$9:$C$38) -> 470.16 | ... Q39: =SUMPRODUCT(Q9:Q38,$C$9:$C$38) -> 954.2

Sheet Report
A1: Robot NI
A2: Earned Value Analysis Report
B4: Prepared By: | C4: COURT Nicolas
B5: Date: | C5: 43532
C6: [42]
B7: For Period: | C7: 2018-2019
A20: Planned Value (PV) or Budgeted Cost of Work Scheduled (BCWS)
A21: WBS | B21: Task Name | C21: BAC | D21: 1 | E21: 2 | F21: 3 | G21: 4 | H21: 5 | I21: 6 | J21: 7 | K21: 8 | L21: 9 | M21: 10 | N21: 11 | O21: 12 | P21: 13 | Q21: 14 | R21: ← You can change the labels for the periods (e.g. Week 1/2/3, Jan/Feb/Mar, etc.)
A22: 1.1 | B22: Arm prototyping & printing | C22: =SUM(D22:Q22) -> 10 | E22: 2 | F22: 4 | G22: 4 | R22: ← Enter or edit values in the light-blue cells.
A23: 1.2 | B23: Assembling model | C23: =SUM(D23:Q23) -> 4 | H23: 4
A24: 2.1 | B24: Sorter prototyping & wood cutting | C24: =SUM(D24:Q24) -> 30 | M24: 30
A25: 2.2 | B25: Change motor (hard+soft) | C25: =SUM(D25:Q25) -> 10 | N25: 10
A26: 2.3 | B26: Assembling model | C26: =SUM(D26:Q26) -> 4 | O26: 4
A27: 2.4 | B27: Update code | C27: =SUM(D27:Q27) -> 8 | O27: 8
A28: 3.1 | B28: Code the Thrower | C28: =SUM(D28:Q28) -> 20 | E28: 20
A29: 3.2 | B29: Electrical mounting | C29: =SUM(D29:Q29) -> 20 | E29: 20
A30: 3.3 | B30: Datasheet on PWM | C30: =SUM(D30:Q30) -> 8 | F30: 8
A31: 4.1 | B31: Executable & Initialisation fn | C31: =SUM(D31:Q31) -> 20 | G31: 8 | H31: 4 | I31: 8
A32: 4.2 | B32: Cleaning code, error cabling ... | C32: =SUM(D32:Q32) -> 32 | H32: 16 | I32: 16
A33: 4.3 | B33: Update all RIO cards | C33: =SUM(D33:Q33) -> 4 | I33: 4
A34: 4.4 | B34: Real Time | C34: =SUM(D34:Q34) -> 56 | I34: 56
A35: 5.1 | B35: Supply PCB prototyping | C35: =SUM(D35:Q35) -> 28 | E35: 4 | F35: 4 | G35: 8 | H35: 4 | Q35: 8
A36: 5.2 | B36: Data PCB Prototyping | C36: =SUM(D36:Q36) -> 80 | I36: 8 | J36: 8 | K36: 32 | L36: 32
A37: 5.3 | B37: PCB Deployment & integration | C37: =SUM(D37:Q37) -> 32 | M37: 4 | N37: 4 | O37: 4 | P37: 4 | Q37: 16
A38: 6.1 | B38: Lidar - Research & command | C38: =SUM(D38:Q38) -> 8 | K38: 8
A39: 6.2 | B39: Lidar - Cabling & Data sending | C39: =SUM(D39:Q39) -> 80 | M39: 40 | N39: 40
A40: 6.3 | B40: Lidar - Data treatment | C40: =SUM(D40:Q40) -> 120 | M40: 40 | N40: 40 | O40: 16 | P40: 16 | Q40: 8
A41: 6.4 | B41: Lidar - Integration on robot | C41: =SUM(D41:Q41) -> 4 | P41: 4
A42: 7.1 | B42: Brainstorming Scenarii & details | C42: =SUM(D42:Q42) -> 8 | E42: 8
A43: 7.2 | B43: Scenario 1 | C43: =SUM(D43:Q43) -> 16 | E43: 8 | F43: 8
A44: 7.3 | B44: Scenario 2 | C44: =SUM(D44:Q44) -> 100 | F44: 16 | H44: 4 | I44: 32 | P44: 32 | Q44: 16
A45: 7.4 | B45: Scenario 3 | C45: =SUM(D45:Q45) -> 18 | F45: 8 | P45: 10
A46: 7.5 | B46: Scenario 4 | C46: =SUM(D46:Q46) -> 58 | M46: 2 | N46: 40 | P46: 16
A47: 8.1 | B47: Preparation & Participation NI | C47: =SUM(D47:Q47) -> 40 | D47: 40
A48: 9.1 | B48: Weekly & project management | C48: =SUM(D48:Q48) -> 212 | E48: 16 | F48: 32 | G48: 16 | H48: 8 | I48: 12 | J48: 8 | K48: 32 | L48: 8 | M48: 8 | N48: 8 | O48: 8 | P48: 8 | Q48: 48
A49: 10.1 | B49: Handover | C49: =SUM(D49:Q49) -> 8 | Q49: 8
A50: 11.1 | B50: JPO presentation | C50: =SUM(D50:Q50) -> 32 | I50: 12 | J50: 10 | P50: 10
A51: Insert new rows above this one | R51: ← To add more tasks, insert rows above this one. You can or delete this row after you are done adding tasks.
B52: Total Budgeted Cost at Completion | C52: =SUM(C22:C51) -> 1070 | D52: =SUM(D22:D51) -> 40 | E52: =SUM(E22:E51) -> 78 | F52: =SUM(F22:F51) -> 80 | G52: =SUM(G22:G51) -> 36 | H52: =SUM(H22:H51) -> 40 | I52: =SUM(I22:I51) -> 148 | J52: =SUM(J22:J51) -> 26 | ... Q52: =SUM(Q22:Q51) -> 104
C53: Cumulative Planned Value (PV) | D53: =IF(ISBLANK(D21),NA(),SUM($D52:D52)) -> 40 | E53: =IF(ISBLANK(E21),NA(),SUM($D52:E52)) -> 118 | F53: =IF(ISBLANK(F21),NA(),SUM($D52:F52)) -> 198 | G53: =IF(ISBLANK(G21),NA(),SUM($D52:G52)) -> 234 | H53: =IF(ISBLANK(H21),NA(),SUM($D52:H52)) -> 274 | I53: =IF(ISBLANK(I21),NA(),SUM($D52:I52)) -> 422 | J53: =IF(ISBLANK(J21),NA(),SUM($D52:J52)) -> 448 | K53: =IF(ISBLANK(K21),NA(),SUM($D52:K52)) -> 520 | ... Q53: =IF(ISBLANK(Q21),NA(),SUM($D52:Q52)) -> 1070
...

Sheet AC
A1: Actual Cost Worksheet
A3: Use this worksheet to help calculate the Actual Cost (AC) of Work Performed (ACWP) by entering the costs incurred each period.
A4: Make sure that the WBS, Task Name, and BAC (Budget at Completion) are identical to the table in the Report worksheet.
A5: Transfer the Cumulative Actual Cost to the Report worksheet.
A7: Actual Cost (AC) of Work Performed
A8: WBS | B8: Task Name | D8: Wk 1 | E8: Wk 2 | F8: Wk 3 | G8: Wk 4 | H8: Wk 5 | I8: Wk 6 | J8: Wk 7 | K8: Wk 8 | L8: Wk 9 | M8: Wk 10 | N8: Wk 11 | O8: Wk 12 | P8: Wk 13 | Q8: Wk 14
A9: =IF(ISBLANK(Report!A22)," - ",Report!A22) -> 1.1 | B9: =IF(ISBLANK(Report!B22)," - ",Report!B22) -> Arm prototyping & printing | E9: 2 | F9: 4 | G9: 4
A10: =IF(ISBLANK(Report!A23)," - ",Report!A23) -> 1.2 | B10: =IF(ISBLANK(Report!B23)," - ",Report!B23) -> Assembling model | H10: 4
A11: =IF(ISBLANK(Report!A24)," - ",Report!A24) -> 2.1 | B11: =IF(ISBLANK(Report!B24)," - ",Report!B24) -> Sorter prototyping & wood cutting | M11: 30
A12: =IF(ISBLANK(Report!A25)," - ",Report!A25) -> 2.2 | B12: =IF(ISBLANK(Report!B25)," - ",Report!B25) -> Change motor (hard+soft) | N12: 20
A13: =IF(ISBLANK(Report!A26)," - ",Report!A26) -> 2.3 | B13: =IF(ISBLANK(Report!B26)," - ",Report!B26) -> Assembling model | O13: 4
A14: =IF(ISBLANK(Report!A27)," - ",Report!A27) -> 2.4 | B14: =IF(ISBLANK(Report!B27)," - ",Report!B27) -> Update code | O14: 8
A15: =IF(ISBLANK(Report!A28)," - ",Report!A28) -> 3.1 | B15: =IF(ISBLANK(Report!B28)," - ",Report!B28) -> Code the Thrower | E15: 20
A16: =IF(ISBLANK(Report!A29)," - ",Report!A29) -> 3.2 | B16: =IF(ISBLANK(Report!B29)," - ",Report!B29) -> Electrical mounting | E16: 20
A17: =IF(ISBLANK(Report!A30)," - ",Report!A30) -> 3.3 | B17: =IF(ISBLANK(Report!B30)," - ",Report!B30) -> Datasheet on PWM | F17: 8
A18: =IF(ISBLANK(Report!A31)," - ",Report!A31) -> 4.1 | B18: =IF(ISBLANK(Report!B31)," - ",Report!B31) -> Executable & Initialisation fn | G18: 8 | H18: 4 | I18: 8
A19: =IF(ISBLANK(Report!A32)," - ",Report!A32) -> 4.2 | B19: =IF(ISBLANK(Report!B32)," - ",Report!B32) -> Cleaning code, error cabling ... | H19: 16 | I19: 16
A20: =IF(ISBLANK(Report!A33)," - ",Report!A33) -> 4.3 | B20: =IF(ISBLANK(Report!B33)," - ",Report!B33) -> Update all RIO cards | I20: 8
A21: =IF(ISBLANK(Report!A34)," - ",Report!A34) -> 4.4 | B21: =IF(ISBLANK(Report!B34)," - ",Report!B34) -> Real Time
A22: =IF(ISBLANK(Report!A35)," - ",Report!A35) -> 5.1 | B22: =IF(ISBLANK(Report!B35)," - ",Report!B35) -> Supply PCB prototyping | E22: 10 | F22: 12 | G22: 12 | H22: 12 | I22: 16 | N22: 16 | Q22: 8
A23: =IF(ISBLANK(Report!A36)," - ",Report!A36) -> 5.2 | B23: =IF(ISBLANK(Report!B36)," - ",Report!B36) -> Data PCB Prototyping | J23: 8 | K23: 32 | L23: 32
A24: =IF(ISBLANK(Report!A37)," - ",Report!A37) -> 5.3 | B24: =IF(ISBLANK(Report!B37)," - ",Report!B37) -> PCB Deployment & integration | M24: 8 | N24: 16 | O24: 8 | P24: 12 | Q24: 16
A25: =IF(ISBLANK(Report!A38)," - ",Report!A38) -> 6.1 | B25: =IF(ISBLANK(Report!B38)," - ",Report!B38) -> Lidar - Research & command | K25: 4 | L25: 2
A26: =IF(ISBLANK(Report!A39)," - ",Report!A39) -> 6.2 | B26: =IF(ISBLANK(Report!B39)," - ",Report!B39) -> Lidar - Cabling & Data sending | M26: 40 | N26: 42
A27: =IF(ISBLANK(Report!A40)," - ",Report!A40) -> 6.3 | B27: =IF(ISBLANK(Report!B40)," - ",Report!B40) -> Lidar - Data treatment | M27: 32 | N27: 40 | O27: 8 | P27: 8 | Q27: 8
A28: =IF(ISBLANK(Report!A41)," - ",Report!A41) -> 6.4 | B28: =IF(ISBLANK(Report!B41)," - ",Report!B41) -> Lidar - Integration on robot | P28: 2
A29: =IF(ISBLANK(Report!A42)," - ",Report!A42) -> 7.1 | B29: =IF(ISBLANK(Report!B42)," - ",Report!B42) -> Brainstorming Scenarii & details | E29: 4
A30: =IF(ISBLANK(Report!A43)," - ",Report!A43) -> 7.2 | B30: =IF(ISBLANK(Report!B43)," - ",Report!B43) -> Scenario 1 | F30: 8 | I30: 8
A31: =IF(ISBLANK(Report!A44)," - ",Report!A44) -> 7.3 | B31: =IF(ISBLANK(Report!B44)," - ",Report!B44) -> Scenario 2 | F31: 16 | G31: 8 | H31: 4 | I31: 60 | P31: 32 | Q31: 16
A32: =IF(ISBLANK(Report!A45)," - ",Report!A45) -> 7.4 | B32: =IF(ISBLANK(Report!B45)," - ",Report!B45) -> Scenario 3 | P32: 10
A33: =IF(ISBLANK(Report!A46)," - ",Report!A46) -> 7.5 | B33: =IF(ISBLANK(Report!B46)," - ",Report!B46) -> Scenario 4
A34: =IF(ISBLANK(Report!A47)," - ",Report!A47) -> 8.1 | B34: =IF(ISBLANK(Report!B47)," - ",Report!B47) -> Preparation & Participation NI | D34: 45
A35: =IF(ISBLANK(Report!A48)," - ",Report!A48) -> 9.1 | B35: =IF(ISBLANK(Report!B48)," - ",Report!B48) -> Weekly & project management | E35: 24 | F35: 32 | G35: 8 | H35: 8 | I35: 12 | J35: 4 | K35: 32 | L35: 8 | M35: 8 | N35: 8 | O35: 4 | P35: 8 | Q35: 48
A36: =IF(ISBLANK(Report!A49)," - ",Report!A49) -> 10.1 | B36: =IF(ISBLANK(Report!B49)," - ",Report!B49) -> Handover | Q36: 8
A37: =IF(ISBLANK(Report!A50)," - ",Report!A50) -> 11.1 | B37: =IF(ISBLANK(Report!B50)," - ",Report!B50) -> JPO presentation | I37: 4 | J37: 30 | P37: 10
A38: Insert new rows above this one
C39: Total Actual Cost | D39: =SUM(D9:D37) -> 45 | E39: =SUM(E9:E37) -> 80 | F39: =SUM(F9:F37) -> 80 | G39: =SUM(G9:G37) -> 40 | H39: =SUM(H9:H37) -> 48 | I39: =SUM(I9:I37) -> 132 | J39: =SUM(J9:J37) -> 42 | K39: =SUM(K9:K37) -> 68 | ... Q39: =SUM(Q9:Q37) -> 104
C41: Cumulative Actual Cost (AC) | D41: =SUM($D39:D39) -> 45 | E41: =SUM($D39:E39) -> 125 | F41: =SUM($D39:F39) -> 205 | G41: =SUM($D39:G39) -> 245 | H41: =SUM($D39:H39) -> 293 | I41: =SUM($D39:I39) -> 425 | J41: =SUM($D39:J39) -> 467 | K41: =SUM($D39:K39) -> 535 | ... Q41: =SUM($D39:Q39) -> 1055
